<?xml version="1.0"?>
<robot name="kr210_arm" xmlns:xacro="http://www.ros.org/wiki/xacro">
<!-- pan_tilt.xacro inorder > pan_tilt_generated.urdf -->
  <!--Define constants-->
  <xacro:property name="pi_" value="3.141592654"/>
  <xacro:property name="deg" value="0.017453293"/><!--degrees to radians-->
  <xacro:property name="mass0" value="1572.9" />
  <xacro:property name="mass1" value="1385.5" />
  <xacro:property name="mass2" value="958.62" />
  <xacro:property name="mass3" value="710.03" />
  <xacro:property name="mass4" value="173.73" />
  <xacro:property name="mass5" value="72.17" />
  <xacro:property name="mass6" value="6.3154" />
  <xacro:property name="gripper_mass" value="3.5" />
  <xacro:property name="finger_mass" value="1.5" />
  <xacro:property name="gripper_type" value="two_finger" /><!--value="vacuum" or "two_finger"-->
  <xacro:property name="vacuum_gripper_radius" value="0.1" />

  <!--Import gazebo elements-->
  <xacro:include filename="$(find kuka_arm_pkg)/urdf/kr210.gazebo.xacro" />

  <!--Links-->
  <link name="base_footprint"/>

  <link name="base_link">
    <inertial>
      <origin xyz="0 0 0" rpy="0 0 0"/>
      <mass value="${mass0}"/>
      <inertia ixx="89.282" ixy="-0.47721" ixz="0.85562" iyy="107.51" iyz="0.0067576" izz="172.02"/>
    </inertial>
    <visual>
      <origin xyz="0 0 0" rpy="${-pi_/2} 0 0"/>
      <geometry>
        <mesh filename="file://$(find kuka_arm_pkg)/meshes/kr210l150/visual/base_link.dae"/>
      </geometry>
      <material name="">
        <color rgba="0.75294 0.75294 0.75294 1"/>
      </material>
    </visual>
    <collision>
      <origin xyz="0 0 0" rpy="${-pi_/2} 0 0"/>
      <geometry>
        <mesh filename="file://$(find kuka_arm_pkg)/meshes/kr210l150/collision/base_link.stl"/>
      </geometry>
    </collision>
  </link>
  <link name="link_1">
    <inertial>
      <origin xyz="0 0 0.4" rpy="0 0 0"/>
      <mass value="${mass1}"/>
      <inertia ixx="90.873" ixy="33.809" ixz="17.159" iyy="147.03" iyz="0.063634" izz="168.19"/>
    </inertial>
    <visual>
      <origin xyz="0 0 0" rpy="0 0 0"/>
      <geometry>
        <mesh filename="file://$(find kuka_arm_pkg)/meshes/kr210l150/visual/link_1.dae"/>
      </geometry>
      <material name="">
        <color rgba="0.75294 0.75294 0.75294 1"/>
      </material>
    </visual>
    <collision>
      <origin xyz="0 0 0" rpy="0 0 0"/>
      <geometry>
        <mesh filename="file://$(find kuka_arm_pkg)/meshes/kr210l150/collision/link_1.stl"/>
      </geometry>
    </collision>
  </link>
  <link name="link_2">
    <inertial>
      <origin xyz="0 0 0.44751" rpy="0 0 0"/>
      <mass value="${mass2}"/>
      <inertia ixx="180.42" ixy="-0.83462" ixz="0.32549" iyy="177.68" iyz="-20.82" izz="20.495"/>
    </inertial>
    <visual>
      <origin xyz="0 0 0" rpy="${-pi_/2} 0 0"/>
      <geometry>
        <mesh filename="file://$(find kuka_arm_pkg)/meshes/kr210l150/visual/link_2.dae"/>
      </geometry>
      <material name="">
        <color rgba="0.75294 0.75294 0.75294 1"/>
      </material>
    </visual>
    <collision>
      <origin xyz="0 0 0" rpy="0 0 0"/>
      <geometry>
        <mesh filename="file://$(find kuka_arm_pkg)/meshes/kr210l150/collision/link_2.stl"/>
      </geometry>
    </collision>
  </link>
  <link name="link_3">
    <inertial>
      <origin xyz="0.18842 0.18344 -0.042799" rpy="0 0 0"/>
      <mass value="${mass3}"/>
      <inertia ixx="11.887" ixy="-0.12154" ixz="-1.3604" iyy="98.805" iyz="-0.056505" izz="96.251"/>
    </inertial>
    <visual>
      <origin xyz="0 -0.184 0" rpy="${-pi_/2} 0 0"/>
      <geometry>
        <mesh filename="file://$(find kuka_arm_pkg)/meshes/kr210l150/visual/link_3.dae"/>
      </geometry>
      <material name="">
        <color rgba="0.75294 0.75294 0.75294 1"/>
      </material>
    </visual>
    <collision>
      <origin xyz="0 -0.184 0" rpy="0 0 0"/>
      <geometry>
        <mesh filename="file://$(find kuka_arm_pkg)/meshes/kr210l150/collision/link_3.stl"/>
      </geometry>
    </collision>
  </link>
  <link name="link_4">
    <inertial>
      <origin xyz="0.27146 -0.007326 0" rpy="0 0 0"/>
      <mass value="${mass4}"/>
      <inertia ixx="1.8001" ixy="-0.18515" ixz="0.00051232" iyy="5.514" iyz="0.00070469" izz="6.3498"/>
    </inertial>
    <visual>
      <origin xyz="0 0 0" rpy="${-pi_/2} 0 0"/>
      <geometry>
        <mesh filename="file://$(find kuka_arm_pkg)/meshes/kr210l150/visual/link_4.dae"/>
      </geometry>
      <material name="">
        <color rgba="0.75294 0.75294 0.75294 1"/>
      </material>
    </visual>
    <collision>
      <origin xyz="0 0 0" rpy="0 0 0"/>
      <geometry>
        <mesh filename="file://$(find kuka_arm_pkg)/meshes/kr210l150/collision/link_4.stl"/>
      </geometry>
    </collision>
  </link>
  <link name="link_5">
    <inertial>
      <origin xyz="0 0 0" rpy="0 0 0"/>
      <mass value="${mass5}"/>
      <inertia ixx="0.3938" ixy="-0.085332" ixz="1.7223E-06" iyy="0.68945" iyz="-7.0292E-06" izz="0.67292"/>
    </inertial>
    <visual>
      <origin xyz="0 0 0" rpy="${-pi_/2} 0 0"/>
      <geometry>
        <mesh filename="file://$(find kuka_arm_pkg)/meshes/kr210l150/visual/link_5.dae"/>
      </geometry>
      <material name="">
        <color rgba="0.75294 0.75294 0.75294 1"/>
      </material>
    </visual>
    <collision>
      <origin xyz="0 0 0" rpy="0 0 0"/>
      <geometry>
        <mesh filename="file://$(find kuka_arm_pkg)/meshes/kr210l150/collision/link_5.stl"/>
      </geometry>
    </collision>
  </link>
  <link name="link_6">
    <inertial>
      <origin xyz="0 0 0" rpy="0 0 0"/>
      <mass value="${mass6}"/>
<inertia ixx="0.031746" ixy="1.7673E-07" ixz="-6.6558E-06" iyy="0.016686" iyz="1.4304E-07" izz="0.016723"/>
    </inertial>
    <visual>
      <origin xyz="0 0 0" rpy="0 0 0"/>
      <geometry>
        <mesh filename="file://$(find kuka_arm_pkg)/meshes/kr210l150/visual/link_6.dae"/>
      </geometry>
      <material name="">
        <color rgba="0.75294 0.75294 0.75294 1"/>
      </material>
    </visual>
    <collision>
      <origin xyz="0 0 0" rpy="0 0 0"/>
      <geometry>
        <mesh filename="file://$(find kuka_arm_pkg)/meshes/kr210l150/collision/link_6.stl"/>
      </geometry>
    </collision>
  </link>

  <!--Gripper links-->
  <!--Vacuum gripper-->
  <xacro:if value="${gripper_type == 'vacuum'}">
  <link name="gripper_link">
    <inertial>
      <origin xyz="0 0 0" rpy="0 0 0"/>
      <mass value="${gripper_mass}"/>
      <inertia ixx="0.05" ixy="0" ixz="0" iyy="0.05" iyz="0" izz="0.05"/>
    </inertial>
    <visual>
      <origin xyz="0 0 0" rpy="0 0 0"/>
      <geometry>
        <sphere radius="${vacuum_gripper_radius}"/>
      </geometry>
    </visual>
    <collision>
      <origin xyz="0 0 0" rpy="0 0 0"/>
      <geometry>
        <sphere radius="${vacuum_gripper_radius}"/>
      </geometry>
    </collision>
  </link>
  <joint name="gripper_joint" type="fixed">
    <parent link="link_6"/>
    <child link="gripper_link"/>
    <origin xyz="0.0375 0 0" rpy="0 0 0"/>
  </joint>
  </xacro:if>

  <!--Two-finger gripper-->
  <xacro:if value="${gripper_type == 'two_finger'}">
  <link name="gripper_link">
    <inertial>
      <origin xyz="0 0 0" rpy="0 0 0"/>
      <mass value="${gripper_mass}"/>
      <inertia ixx="0.001" ixy="0" ixz="0" iyy="0.002" iyz="0" izz="0.001"/>
    </inertial>
    <visual>
      <origin xyz="0 0 0" rpy="0 0 0"/>
      <geometry>
        <mesh filename="file://$(find kuka_arm_pkg)/meshes/gripper/gripper_base.dae"/>
      </geometry>
    </visual>
    <collision>
      <origin xyz="0 0 0" rpy="0 0 0"/>
      <geometry>
        <mesh filename="file://$(find kuka_arm_pkg)/meshes/gripper/gripper_base.dae"/>
      </geometry>
    </collision>
  </link>
  <link name="right_gripper_finger_link">
    <inertial>
      <origin xyz="0 0 0" rpy="0 0 0"/>
      <mass value="${finger_mass}"/>
      <inertia ixx="0.002" ixy="0" ixz="0" iyy="0.002" iyz="0" izz="0.002"/>
    </inertial>
    <visual>
      <origin xyz="0 0 0" rpy="0 0 0"/>
      <geometry>
        <mesh filename="file://$(find kuka_arm_pkg)/meshes/gripper/finger_right.dae"/>
      </geometry>
    </visual>
    <collision>
      <origin xyz="0 0 0" rpy="0 0 0"/>
      <geometry>
        <mesh filename="file://$(find kuka_arm_pkg)/meshes/gripper/finger_right_collision.dae"/>
      </geometry>
    </collision>
  </link>
  <link name="left_gripper_finger_link">
    <inertial>
      <origin xyz="0 0 0" rpy="0 0 0"/>
      <mass value="${finger_mass}"/>
      <inertia ixx="0.002" ixy="0" ixz="0" iyy="0.002" iyz="0" izz="0.002"/>
    </inertial>
    <visual>
      <origin xyz="0 0 0" rpy="0 0 0"/>
      <geometry>
        <mesh filename="file://$(find kuka_arm_pkg)/meshes/gripper/finger_left.dae"/>
      </geometry>
    </visual>
    <collision>
      <origin xyz="0 0 0" rpy="0 0 0"/>
      <geometry>
        <mesh filename="file://$(find kuka_arm_pkg)/meshes/gripper/finger_left_collision.dae"/>
      </geometry>
    </collision>
  </link>

  <joint name="right_gripper_finger_joint" type="prismatic">
    <origin rpy="0 0 0" xyz="0.15 -0.0725 0" />
    <parent link="gripper_link" />
    <child link="right_gripper_finger_link" />
    <axis xyz="0 1 0" />
    <limit effort="100" lower="-0.01" upper="0.06" velocity="0.05" />
    <dynamics damping="0.7" />
  </joint>
  <joint name="left_gripper_finger_joint" type="prismatic">
    <origin rpy="0 0 0" xyz="0.15 0.0725 0" />
    <parent link="gripper_link" />
    <child link="left_gripper_finger_link" />
    <axis xyz="0 -1 0" />
    <limit effort="100" lower="-0.01" upper="0.06" velocity="0.05" />
    <dynamics damping="0.7" />
  </joint>
  <joint name="gripper_joint" type="fixed">
    <parent link="link_6"/>
    <child link="gripper_link"/>
    <origin xyz="0.11 0 0" rpy="0 0 0"/><!--0.087-->
    <axis xyz="0 1 0" />
  </joint>



  </xacro:if>

  <!-- joints -->
  <joint name="fixed_base_joint" type="fixed">
    <parent link="base_footprint"/>
    <child link="base_link"/>
    <origin xyz="0 0 0" rpy="0 0 0"/>
  </joint>
  <joint name="joint_1" type="revolute">
    <origin xyz="0 0 0.33" rpy="0 0 0"/>
    <parent link="base_link"/>
    <child link="link_1"/>
    <axis xyz="0 0 1"/>
    <limit lower="${-185*deg}" upper="${185*deg}" effort="300" velocity="${123*deg}"/>
<dynamics damping="10000.0" friction="10000.0"/>
  </joint>
  <joint name="joint_2" type="revolute">
    <origin xyz="0.35 0 0.42" rpy="0 0 0"/>
    <parent link="link_1"/>
    <child link="link_2"/>
    <axis xyz="0 1 0"/>
    <limit lower="${-45*deg}" upper="${85*deg}" effort="300" velocity="${115*deg}"/>
<dynamics damping="10000.0" friction="10000.0"/>
  </joint>
  <joint name="joint_3" type="revolute">
    <origin xyz="0 0 1.25" rpy="0 0 0"/>
    <parent link="link_2"/>
    <child link="link_3"/>
    <axis xyz="0 1 0"/>
    <limit lower="${-210*deg}" upper="${(155-90)*deg}" effort="300" velocity="${112*deg}"/>
<dynamics damping="10000.0" friction="10000.0"/>
  </joint>
  <joint name="joint_4" type="revolute">
    <origin xyz="0.96 0 -0.054" rpy="0 0 0"/>
    <parent link="link_3"/>
    <child link="link_4"/>
    <axis xyz="1 0 0"/>
    <limit lower="${-350*deg}" upper="${350*deg}" effort="300" velocity="${179*deg}"/>
<dynamics damping="10000.0" friction="10000.0"/>
  </joint>
  <joint name="joint_5" type="revolute">
    <origin xyz="0.54 0 0" rpy="0 0 0"/>
    <parent link="link_4"/>
    <child link="link_5"/>
    <axis xyz="0 1 0"/>
    <limit lower="${-125*deg}" upper="${125*deg}" effort="300" velocity="${172*deg}"/>
<dynamics damping="10000.0" friction="10000.0"/>
  </joint>
  <joint name="joint_6" type="revolute">
    <origin xyz="0.193 0 0" rpy="0 0 0"/>
    <parent link="link_5"/>
    <child link="link_6"/>
    <axis xyz="1 0 0"/>
    <limit lower="${-350*deg}" upper="${350*deg}" effort="300" velocity="${219*deg}"/>
<dynamics damping="10000.0" friction="10000.0"/>
  </joint>



</robot>
